Workbook

Sheet Read Me
A1: Exploratory Data Analysis (EDA): Practical Workbook
A3: Purpose | B3: Explore 12 months of retail sales before forecasting: seasonal pattern, relationship between advertising and sales, unusual observations, descriptive statistics, data quality, and business insights.
A4: Scenario | B4: A retail business reviews monthly performance over one financial year (April to March).
A5: Dataset period | B5: April to March (12 months, financial-year order).
A6: Source of truth | B6: Raw Dataset A1:D13
A7: Correlation vs causation | B7: A strong correlation between advertising and sales shows association only. It does not prove advertising causes higher sales; festivals, pricing, offers and stock may influence both.
A9: Variables
A10: Variable | B10: Unit | C10: Data type
A11: Month | B11: April to March | C11: Time label (text)
A12: Advertising | B12: ₹ thousand | C12: Continuous (numeric)
A13: Sales | B13: ₹ lakh | C13: Continuous (numeric)
A14: Orders | B14: Number | C14: Discrete (numeric)

Sheet Raw Dataset
A1: Month | B1: Advertising (₹ thousand) | C1: Sales (₹ lakh) | D1: Orders
A2: Apr | B2: 48 | C2: 18.2 | D2: 420
A3: May | B3: 52 | C3: 19.5 | D3: 431
A4: Jun | B4: 60 | C4: 17.9 | D4: 410
A5: Jul | B5: 50 | C5: 20.8 | D5: 458
A6: Aug | B6: 66 | C6: 21.5 | D6: 497
A7: Sep | B7: 55 | C7: 23 | D7: 466
A8: Oct | B8: 82 | C8: 31.5 | D8: 660
A9: Nov | B9: 105 | C9: 44.8 | D9: 905
A10: Dec | B10: 90 | C10: 27.6 | D10: 598
A11: Jan | B11: 58 | C11: 22.4 | D11: 520
A12: Feb | B12: 50 | C12: 21.2 | D12: 455
A13: Mar | B13: 70 | C13: 24.6 | D13: 548

Sheet Data Quality Checks
A1: Data Quality Checks
A3: Check | B3: Formula result | C3: Expected | D3: Status | E3: Excel formula used | F3: Interpretation
A4: Number of monthly records | B4: =COUNTA('Raw Dataset'!$A$2:$A$13) -> 12 | C4: 12 | D4: =IF(B4=C4,"PASS","REVIEW") -> PASS | E4: =COUNTA(A2:A13) | F4: 12 months, April to March.
A5: Blank cells in numeric columns | B5: =COUNTBLANK('Raw Dataset'!$B$2:$D$13) -> 0 | C5: 0 | D5: =IF(B5=C5,"PASS","REVIEW") -> PASS | E5: =COUNTBLANK(B2:D13) | F5: No missing advertising, sales or order values.
A6: Blank month labels | B6: =COUNTBLANK('Raw Dataset'!$A$2:$A$13) -> 0 | C6: 0 | D6: =IF(B6=C6,"PASS","REVIEW") -> PASS | E6: =COUNTBLANK(A2:A13) | F6: Every record has a month label.
A7: Numeric advertising entries | B7: =COUNT('Raw Dataset'!$B$2:$B$13) -> 12 | C7: 12 | D7: =IF(B7=C7,"PASS","REVIEW") -> PASS | E7: =COUNT(B2:B13) | F7: All advertising values are stored as numbers.
A8: Numeric sales entries | B8: =COUNT('Raw Dataset'!$C$2:$C$13) -> 12 | C8: 12 | D8: =IF(B8=C8,"PASS","REVIEW") -> PASS | E8: =COUNT(C2:C13) | F8: All sales values are stored as numbers.
A9: Numeric order entries | B9: =COUNT('Raw Dataset'!$D$2:$D$13) -> 12 | C9: 12 | D9: =IF(B9=C9,"PASS","REVIEW") -> PASS | E9: =COUNT(D2:D13) | F9: All order counts are stored as numbers.
A10: Duplicate month labels | B10: =SUMPRODUCT(--(COUNTIF('Raw Dataset'!$A$2:$A$13,'Raw Dataset'!$A$2:$A$13)>1)) -> 0 | C10: 0 | D10: =IF(B10=C10,"PASS","REVIEW") -> PASS | E10: =SUMPRODUCT(--(COUNTIF(A2:A13,A2:A13)>1)) | F10: Each month appears once.
A11: Duplicate complete records | B11: =SUMPRODUCT(--(COUNTIFS('Raw Dataset'!$A$2:$A$13,'Raw Dataset'!$A$2:$A$13,'Raw Dataset'!$B$2:$B$13,'Raw Dataset'!$B$2:$B$13,'Raw Dataset'!$C$2:$C$13,'Raw Dataset'!$C$2:$C$13,'Raw Dataset'!$D$2:$D$13,'Raw Dataset'!$D$2:$D$13)>1)) -> 0 | C11: 0 | D11: =IF(B11=C11,"PASS","REVIEW") -> PASS | E11: =SUMPRODUCT(--(COUNTIFS(A2:A13,A2:A13,B2:B13,B2:B13,C2:C13,C2:C13,D2:D13,D2:D13)>1)) | F11: No duplicate rows.
A12: Advertising values > 0 | B12: =COUNTIF('Raw Dataset'!$B$2:$B$13,">0") -> 12 | C12: 12 | D12: =IF(B12=C12,"PASS","REVIEW") -> PASS | E12: =COUNTIF(B2:B13,">0") | F12: All advertising values are positive.
A13: Sales values > 0 | B13: =COUNTIF('Raw Dataset'!$C$2:$C$13,">0") -> 12 | C13: 12 | D13: =IF(B13=C13,"PASS","REVIEW") -> PASS | E13: =COUNTIF(C2:C13,">0") | F13: All sales values are positive.
A15: OVERALL DATA QUALITY | B15: =COUNTIF(D4:D13,"PASS")&" of "&ROWS(D4:D13)&" passed" -> 10 of 10 passed

Sheet Descriptive Statistics
A1: Descriptive Statistics: Monthly Sales (₹ lakh)
A3: Statistic | B3: Value | C3: Excel formula used | D3: Business interpretation
A4: Count (numeric sales entries) | B4: =COUNT('Raw Dataset'!$C$2:$C$13) -> 12 | C4: =COUNT(C2:C13) | D4: All 12 months have numeric sales.
A5: Mean | B5: =AVERAGE('Raw Dataset'!$C$2:$C$13) -> 24.416667 | C5: =AVERAGE(C2:C13) | D5: Typical month, but pulled upward by the festive peak.
A6: Median | B6: =MEDIAN('Raw Dataset'!$C$2:$C$13) -> 21.95 | C6: =MEDIAN(C2:C13) | D6: A more typical month; mean > median indicates right skew.
A7: Minimum | B7: =MIN('Raw Dataset'!$C$2:$C$13) -> 17.9 | C7: =MIN(C2:C13) | D7: Weakest month; a planning floor for cash flow.
A8: Maximum | B8: =MAX('Raw Dataset'!$C$2:$C$13) -> 44.8 | C8: =MAX(C2:C13) | D8: Peak demand; check stock and staffing capacity.
A9: Range (Max - Min) | B9: =B8-B7 -> 26.9 | C9: =MAX-MIN | D9: Gap between best and weakest month.
A10: First quartile (Q1) | B10: =_xlfn.QUARTILE.INC('Raw Dataset'!$C$2:$C$13,1) -> 20.475 | C10: =QUARTILE.INC(C2:C13,1) | D10: 25% of months sell below this level.
A11: Third quartile (Q3) | B11: =_xlfn.QUARTILE.INC('Raw Dataset'!$C$2:$C$13,3) -> 25.35 | C11: =QUARTILE.INC(C2:C13,3) | D11: 75% of months sell below this level.
A12: Interquartile range (IQR) | B12: =B11-B10 -> 4.875 | C12: =Q3-Q1 | D12: Spread of the middle 50% of months; robust to the peak.
A13: Sample variance | B13: =_xlfn.VAR.S('Raw Dataset'!$C$2:$C$13) -> 56.283333 | C13: =VAR.S(C2:C13) | D13: Squared ₹ lakh; used to derive the standard deviation.
A14: Sample standard deviation | B14: =_xlfn.STDEV.S('Raw Dataset'!$C$2:$C$13) -> 7.5022219 | C14: =STDEV.S(C2:C13) | D14: Months typically differ from the mean by about ₹7.5 lakh.
A15: Population standard deviation | B15: =_xlfn.STDEV.P('Raw Dataset'!$C$2:$C$13) -> 7.1828306 | C15: =STDEV.P(C2:C13) | D15: Shown for comparison; the deck uses the sample version (12 months = a sample).
A16: Coefficient of variation (%) | B16: =B14/B5*100 -> 30.725823 | C16: =STDEV.S/AVERAGE*100 | D16: Variability is about 30.7% of the mean: moderately high.
A17: Lower outlier fence | B17: =B10-1.5*B12 -> 13.1625 | C17: =Q1-1.5*IQR | D17: Values below this would be flagged.
A18: Upper outlier fence | B18: =B11+1.5*B12 -> 32.6625 | C18: =Q3+1.5*IQR | D18: Values above this are flagged for investigation.
A19: Observations flagged as potential outliers | B19: =COUNTIF('Raw Dataset'!$C$2:$C$13,">"&B18)+COUNTIF('Raw Dataset'!$C$2:$C$13,"<"&B17) -> 1 | C19: =COUNTIF(>UF)+COUNTIF(<LF) | D19: Only one of 12 months is flagged.
A20: Flagged month (if any, above upper fence) | B20: =IF(COUNTIF('Raw Dataset'!$C$2:$C$13,">"&B18)>0,INDEX('Raw Dataset'!$A$2:$A$13,MATCH(B8,'Raw Dataset'!$C$2:$C$13,0)),"None") -> Nov | C20: =IF(COUNTIF(>UF)>0,month of MAX,"None") | D20: November: a flag for investigation, not a reason to delete.

Sheet Univariate Analysis
A1: Univariate Analysis: Monthly Sales (₹ lakh)
A2: All counts are formulas on 'Raw Dataset'!C2:C13. Blue cells are adjustable thresholds / reference values.
A4: A. Sales bands
A5: Low / Medium threshold (₹ lakh) | B5: 20
A6: Medium / High threshold (₹ lakh) | B6: 30
A8: Band | B8: Definition | C8: Months | D8: % of months | E8: PPT reference | F8: Check
A9: Low | B9: ="Below ₹"&B5&" lakh" -> Below ₹20 lakh | C9: =COUNTIF('Raw Dataset'!$C$2:$C$13,"<"&B5) -> 3 | D9: =C9/$C$12 -> 0.25 | E9: 3 | F9: =IF(C9=E9,"Match","Differs") -> Match
A10: Medium | B10: ="₹"&B5&" lakh to below ₹"&B6&" lakh" -> ₹20 lakh to below ₹30 lakh | C10: =COUNTIFS('Raw Dataset'!$C$2:$C$13,">="&B5,'Raw Dataset'!$C$2:$C$13,"<"&B6) -> 7 | D10: =C10/$C$12 -> 0.58333333 | E10: 7 | F10: =IF(C10=E10,"Match","Differs") -> Match
A11: High | B11: ="₹"&B6&" lakh or more" -> ₹30 lakh or more | C11: =COUNTIF('Raw Dataset'!$C$2:$C$13,">="&B6) -> 2 | D11: =C11/$C$12 -> 0.16666667 | E11: 2 | F11: =IF(C11=E11,"Match","Differs") -> Match
A12: Total | C12: =SUM(C9:C11) -> 12 | D12: =SUM(D9:D11) -> 1 | E12: 12 | F12: =IF(C12=COUNT('Raw Dataset'!$C$2:$C$13),"Match","Differs") -> Match
A14: B. Frequency table (histogram bins of ₹ 5 lakh)
A15: First bin lower limit (₹ lakh) | B15: 15
A16: Bin width (₹ lakh) | B16: 5
A18: Bin (₹ lakh) | B18: Lower (inclusive) | C18: Upper (exclusive) | D18: Frequency (months) | E18: % of months | F18: Cumulative % | G18: PPT reference | H18: Check
A19: =B19&"–"&C19 -> 15–20 | B19: =$B$15+$B$16*0 -> 15 | C19: =B19+$B$16 -> 20 | D19: =COUNTIFS('Raw Dataset'!$C$2:$C$13,">="&B19,'Raw Dataset'!$C$2:$C$13,"<"&C19) -> 3 | E19: =D19/$D$25 -> 0.25 | F19: =SUM($D$19:D19)/$D$25 -> 0.25 | G19: 3 | H19: =IF(D19=G19,"Match","Differs") -> Match
A20: =B20&"–"&C20 -> 20–25 | B20: =$B$15+$B$16*1 -> 20 | C20: =B20+$B$16 -> 25 | D20: =COUNTIFS('Raw Dataset'!$C$2:$C$13,">="&B20,'Raw Dataset'!$C$2:$C$13,"<"&C20) -> 6 | E20: =D20/$D$25 -> 0.5 | F20: =SUM($D$19:D20)/$D$25 -> 0.75 | G20: 6 | H20: =IF(D20=G20,"Match","Differs") -> Match
A21: =B21&"–"&C21 -> 25–30 | B21: =$B$15+$B$16*2 -> 25 | C21: =B21+$B$16 -> 30 | D21: =COUNTIFS('Raw Dataset'!$C$2:$C$13,">="&B21,'Raw Dataset'!$C$2:$C$13,"<"&C21) -> 1 | E21: =D21/$D$25 -> 0.083333333 | F21: =SUM($D$19:D21)/$D$25 -> 0.83333333 | G21: 1 | H21: =IF(D21=G21,"Match","Differs") -> Match
A22: =B22&"–"&C22 -> 30–35 | B22: =$B$15+$B$16*3 -> 30 | C22: =B22+$B$16 -> 35 | D22: =COUNTIFS('Raw Dataset'!$C$2:$C$13,">="&B22,'Raw Dataset'!$C$2:$C$13,"<"&C22) -> 1 | E22: =D22/$D$25 -> 0.083333333 | F22: =SUM($D$19:D22)/$D$25 -> 0.91666667 | G22: 1 | H22: =IF(D22=G22,"Match","Differs") -> Match
A23: =B23&"–"&C23 -> 35–40 | B23: =$B$15+$B$16*4 -> 35 | C23: =B23+$B$16 -> 40 | D23: =COUNTIFS('Raw Dataset'!$C$2:$C$13,">="&B23,'Raw Dataset'!$C$2:$C$13,"<"&C23) -> 0 | E23: =D23/$D$25 -> 0 | F23: =SUM($D$19:D23)/$D$25 -> 0.91666667 | G23: 0 | H23: =IF(D23=G23,"Match","Differs") -> Match
A24: =B24&"–"&C24 -> 40–45 | B24: =$B$15+$B$16*5 -> 40 | C24: =B24+$B$16 -> 45 | D24: =COUNTIFS('Raw Dataset'!$C$2:$C$13,">="&B24,'Raw Dataset'!$C$2:$C$13,"<"&C24) -> 1 | E24: =D24/$D$25 -> 0.083333333 | F24: =SUM($D$19:D24)/$D$25 -> 1 | G24: 1 | H24: =IF(D24=G24,"Match","Differs") -> Match
A25: Total | D25: =SUM(D19:D24) -> 12 | E25: =SUM(E19:E24) -> 1 | H25: =IF(D25=COUNT('Raw Dataset'!$C$2:$C$13),"All values binned","Check bins") -> All values binned
A26: Bins are lower-inclusive, upper-exclusive (e.g. 20.0 belongs to 20–25), matching the slide-24 histogram counts 3, 6, 1, 1, 0, 1.
A28: C. Centre and spread
A29: Measure | B29: Value | C29: Reading
A30: Mean (₹ lakh) | B30: ='Descriptive Statistics'!$B$5 -> 24.416667 | C30: =IF(B30>B31,"Mean above median: right-skewed (pulled up by the peak month)",IF(B30<B31,"Mean below median: left-skewed","Mean equals median: roughly symmetric")) -> Mean above median: right-skewed (pulled up by the peak month) | G30: right-skewness
A31: Median (₹ lakh) | B31: ='Descriptive Statistics'!$B$6 -> 21.95 | C31: Middle month; less affected by extremes.
A32: Mean minus median (₹ lakh) | B32: =B30-B31 -> 2.4666667 | C32: Positive gap signals the influence of high values.
A33: Range (₹ lakh) | B33: ='Descriptive Statistics'!$B$9 -> 26.9 | C33: Highest minus lowest month.
A34: IQR (₹ lakh) | B34: ='Descriptive Statistics'!$B$12 -> 4.875 | C34: Spread of the central 50% of months.
A35: Sample standard deviation (₹ lakh) | B35: ='Descriptive Statistics'!$B$14 -> 7.5022219 | C35: Typical distance from the mean.
A36: Coefficient of variation (%) | B36: ='Descriptive Statistics'!$B$16 -> 30.725823 | C36: Relative variability: SD / mean.
A37: Lower fence (₹ lakh) | B37: ='Descriptive Statistics'!$B$17 -> 13.1625 | C37: Q1 - 1.5 x IQR.
A38: Upper fence (₹ lakh) | B38: ='Descriptive Statistics'!$B$18 -> 32.6625 | C38: Q3 + 1.5 x IQR.
A39: Potential outliers (count) | B39: ='Descriptive Statistics'!$B$19 -> 1 | C39: Flags for investigation, not for deletion.
A42: D. Month-by-month classification and outlier identification
A43: Month | B43: Sales (₹ lakh) | C43: Band | D43: Outlier flag
A44: ='Raw Dataset'!A2 -> Apr | B44: ='Raw Dataset'!C2 -> 18.2 | C44: =IF(B44<$B$5,"Low",IF(B44<$B$6,"Medium","High")) -> Low | D44: =IF(OR(B44>'Descriptive Statistics'!$B$18,B44<'Descriptive Statistics'!$B$17),"Potential outlier","Within fences") -> Within fences
A45: ='Raw Dataset'!A3 -> May | B45: ='Raw Dataset'!C3 -> 19.5 | C45: =IF(B45<$B$5,"Low",IF(B45<$B$6,"Medium","High")) -> Low | D45: =IF(OR(B45>'Descriptive Statistics'!$B$18,B45<'Descriptive Statistics'!$B$17),"Potential outlier","Within fences") -> Within fences
A46: ='Raw Dataset'!A4 -> Jun | B46: ='Raw Dataset'!C4 -> 17.9 | C46: =IF(B46<$B$5,"Low",IF(B46<$B$6,"Medium","High")) -> Low | D46: =IF(OR(B46>'Descriptive Statistics'!$B$18,B46<'Descriptive Statistics'!$B$17),"Potential outlier","Within fences") -> Within fences
A47: ='Raw Dataset'!A5 -> Jul | B47: ='Raw Dataset'!C5 -> 20.8 | C47: =IF(B47<$B$5,"Low",IF(B47<$B$6,"Medium","High")) -> Medium | D47: =IF(OR(B47>'Descriptive Statistics'!$B$18,B47<'Descriptive Statistics'!$B$17),"Potential outlier","Within fences") -> Within fences
...

Sheet Charts and Dashboard
A1: Charts and Dashboard: Retail EDA
J42: Correlation matrix / heatmap (Pearson r)
J43: Variable | K43: Advertising | M43: Sales | O43: Orders
J44: Advertising | K44: =CORREL('Raw Dataset'!$B$2:$B$13,'Raw Dataset'!$B$2:$B$13) -> 1 | M44: =CORREL('Raw Dataset'!$B$2:$B$13,'Raw Dataset'!$C$2:$C$13) -> 0.89941744 | O44: =CORREL('Raw Dataset'!$B$2:$B$13,'Raw Dataset'!$D$2:$D$13) -> 0.91930273
J45: Sales | K45: =CORREL('Raw Dataset'!$C$2:$C$13,'Raw Dataset'!$B$2:$B$13) -> 0.89941744 | M45: =CORREL('Raw Dataset'!$C$2:$C$13,'Raw Dataset'!$C$2:$C$13) -> 1 | O45: =CORREL('Raw Dataset'!$C$2:$C$13,'Raw Dataset'!$D$2:$D$13) -> 0.99237169
J46: Orders | K46: =CORREL('Raw Dataset'!$D$2:$D$13,'Raw Dataset'!$B$2:$B$13) -> 0.91930273 | M46: =CORREL('Raw Dataset'!$D$2:$D$13,'Raw Dataset'!$C$2:$C$13) -> 0.99237169 | O46: =CORREL('Raw Dataset'!$D$2:$D$13,'Raw Dataset'!$D$2:$D$13) -> 1
J48: Darker blue = stronger positive correlation (scale 0 to 1).
J49: ="Advertising–sales r = "&TEXT(M44,"0.000")&"; sales–orders r = "&TEXT(O45,"0.000")&". Correlation measures association only." -> Advertising–sales r = 0.899; sales–orders r = 0.992. Correlation measures association only.
